<mujoco model="ainex">
  <compiler angle="radian" meshdir="../meshes/" eulerseq="zyx" autolimits="true"/>
  <option timestep='0.001' iterations='50' solver='PGS' gravity='0 0 -9.81'>
    <!-- <flag sensornoise="enable" frictionloss="enable"/> -->
  </option>
  <size njmax="500" nconmax="100" />
  <asset>
    <material name="grid_mat" texture="grid" texrepeat="10 10" texuniform="true" rgba="1 1 1 1"/>
    <texture name="grid" type="2d" builtin="checker" width="512" height="512" rgb1="0.8 0.8 0.8" rgb2="0.2 0.2 0.2"/>
    <mesh name="body_link" file="body_link.STL"/>
    <mesh name="r_hip_yaw_link" file="r_hip_yaw_link.STL"/>
    <mesh name="r_hip_roll_link" file="r_hip_roll_link.STL"/>
    <mesh name="r_hip_pitch_link" file="r_hip_pitch_link.STL"/>
    <mesh name="r_knee_link" file="r_knee_link.STL"/>
    <mesh name="r_ank_pitch_link" file="r_ank_pitch_link.STL"/>
    <mesh name="r_ank_roll_link" file="r_ank_roll_link.STL"/>
    <mesh name="l_hip_yaw_link" file="l_hip_yaw_link.STL"/>
    <mesh name="l_hip_roll_link" file="l_hip_roll_link.STL"/>
    <mesh name="l_hip_pitch_link" file="l_hip_pitch_link.STL"/>
    <mesh name="l_knee_link" file="l_knee_link.STL"/>
    <mesh name="l_ank_pitch_link" file="l_ank_pitch_link.STL"/>
    <mesh name="l_ank_roll_link" file="l_ank_roll_link.STL"/>
    <mesh name="head_pan_link" file="head_pan_link.STL"/>
    <mesh name="head_tilt_link" file="head_tilt_link.STL"/>
    <mesh name="r_sho_pitch_link" file="r_sho_pitch_link.STL"/>
    <mesh name="r_sho_roll_link" file="r_sho_roll_link.STL"/>
    <mesh name="r_el_pitch_link" file="r_el_pitch_link.STL"/>
    <mesh name="r_el_yaw_link" file="r_el_yaw_link.STL"/>
    <mesh name="r_gripper_link" file="r_gripper_link.STL"/>
    <mesh name="l_sho_pitch_link" file="l_sho_pitch_link.STL"/>
    <mesh name="l_sho_roll_link" file="l_sho_roll_link.STL"/>
    <mesh name="l_el_pitch_link" file="l_el_pitch_link.STL"/>
    <mesh name="l_el_yaw_link" file="l_el_yaw_link.STL"/>
    <mesh name="l_gripper_link" file="l_gripper_link.STL"/>
  </asset>
  <default>
      <joint limited='true' damping='0.01' frictionloss='0.05'/>
      <motor ctrllimited='true'/>
      <equality solref='0.001 2'/>
      <geom condim='3' contype='4' conaffinity='0' solref='0.001 2' friction='0.8 0.2 0.2' />
  </default>
  <worldbody>
    <light directional="true" diffuse=".4 .4 .4" specular="0.1 0.1 0.1" pos="0 0 5.0" dir="0 0 -1" castshadow="false"/>
    <light directional="true" diffuse=".6 .6 .6" specular="0.2 0.2 0.2" pos="0 0 4" dir="0 0 -1"/>
    <geom name="floor" size="10 10 0.1" pos="0.0 0 0" condim="3"  conaffinity="15" type="plane" material="grid_mat"/>
    <body name="base_link" pos="0 0 0.25" >
      <freejoint/>
      <inertial pos="-0.002 -7.92910841109997E-05 0.00804544952747596" mass="0.743"  diaginertia="0.00121619  0.00104402  0.00108564" />
      <geom type="mesh" mesh="body_link" rgba="0.1 0.1 0.1 1" /> 
      <site name='imu' size='0.01' pos='0.0 0 0.0'/>
    <body name="l_hip_yaw_link" pos="0 0.029 0">
      <inertial pos="-3.11406e-05 -0.00125722 -0.0013713" quat="0.727661 -0.0116933 0.0358264 0.684901" mass="0.032" diaginertia="2.27801e-05 1.75528e-05 8.97707e-06"/>
      <joint name="l_hip_yaw" pos="0 0 0" axis="0 0 -1" range="-2.09 2.09"  />
      <geom type="mesh" rgba="0.4 0.9 0.4 1" mesh="l_hip_yaw_link"/>
      <body name="l_hip_roll_link" pos="-0.01955 0 -0.0255">
        <inertial pos="0.00136239 0.000566861 -0.0134187" quat="0.508887 0.501276 0.491474 0.498207" mass="0.12" diaginertia="7.31184e-05 6.05065e-05 2.91551e-05"/>
        <joint name="l_hip_roll" pos="0 0 0" axis="-1 0 0" range="-2.09 2.09"  />
        <geom type="mesh" rgba="0.4 0.9 0.4 1" mesh="l_hip_roll_link"/>
        <body name="l_hip_pitch_link" pos="0.019037 0.02 0">
          <inertial pos="0.0135944 -0.0193812 -0.0727051" quat="0.671181 0.0407745 0.0427036 0.738938" mass="0.1065" diaginertia="0.000112942 0.000111046 4.06518e-05"/>
          <joint name="l_hip_pitch" pos="0 0 0" axis="0 1 0" range="-2.09 2.09"  />
          <geom type="mesh" rgba="0.4 0.9 0.4 1" mesh="l_hip_pitch_link"/>
          <body name="l_knee_link" pos="-0.00037204 -5e-05 -0.096886">
            <inertial pos="0.00334256 -0.0196465 -0.0425053" quat="0.999536 8.38713e-05 -0.0304236 -0.00159474" mass="0.045" diaginertia="6.75038e-05 5.49999e-05 2.05563e-05"/>
            <joint name="l_knee" pos="0 0 0" axis="0 1 0" range="-2.09 2.09"  />
            <geom type="mesh" rgba="0.4 0.9 0.4 1" mesh="l_knee_link"/>
            <body name="l_ank_pitch_link" pos="0.001037 0 -0.089077">
              <inertial pos="-0.017544 -0.0195632 0.0134182" quat="0.503197 0.510389 0.496862 0.489309" mass="0.12" diaginertia="7.36835e-05 6.10769e-05 2.91596e-05"/>
              <joint name="l_ank_pitch" pos="0 0 0" axis="0 -1 0" range="-2.09 2.09" frictionloss="0.2" />
              <geom type="mesh" rgba="0.4 0.9 0.4 1" mesh="l_ank_pitch_link"/>
              <body name="l_ank_roll_link" pos="-0.019037 -0.02 0.0">
                <inertial pos="0.028508 0.012873 -0.017671" quat="-0.0257514 0.696659 -0.0389182 0.715883" mass="0.0675" diaginertia="0.000126012 9.21991e-05 4.20891e-05"/>
                <joint name="l_ank_roll" pos="0 0 0" axis="1 0 0" range="-2.09 2.09" frictionloss="0.2" />
                <!-- <geom type="mesh" rgba="0.4 0.9 0.4 1" mesh="l_ank_roll_link" condim="3" contype="1" conaffinity="2"/> -->
                <geom type="box" pos="0.03 0.015 -0.02" size="0.06 0.04 0.002" rgba="0.4 0.9 0.4 1" contype="1" conaffinity="2"/>
              </body>
            </body>
          </body>
        </body>
      </body>
    </body>
    <body name="r_hip_yaw_link" pos="0 -0.029 0">
      <inertial pos="-3.08089e-05 0.00125727 -0.00137107" quat="0.685451 0.035864 -0.0116524 0.727142" mass="0.032" diaginertia="2.27792e-05 1.75538e-05 8.97703e-06"/>
      <joint name="r_hip_yaw" pos="0 0 0" axis="0 0 -1" range="-2.09 2.09"  />
      <geom type="mesh" rgba="0.4 0.9 0.4 1" mesh="r_hip_yaw_link"/>
      <body name="r_hip_roll_link" pos="-0.01955 0 -0.0255">
        <inertial pos="0.0013624 -0.000566876 -0.0134187" quat="0.498207 0.491474 0.501276 0.508887" mass="0.12" diaginertia="7.31184e-05 6.05065e-05 2.91551e-05"/>
        <joint name="r_hip_roll" pos="0 0 0" axis="-1 0 0" range="-2.09 2.09"  />
        <geom type="mesh" rgba="0.4 0.9 0.4 1" mesh="r_hip_roll_link"/>
        <body name="r_hip_pitch_link" pos="0.0190366 -0.02 0">
          <inertial pos="0.0135944 0.0193812 -0.0727054" quat="0.738938 0.0427036 0.0407745 0.671181" mass="0.1065" diaginertia="0.000112942 0.000111046 4.06518e-05"/>
          <joint name="r_hip_pitch" pos="0 0 0" axis="0 -1 0" range="-2.09 2.09"  />
          <geom type="mesh" rgba="0.4 0.9 0.4 1" mesh="r_hip_pitch_link"/>
          <body name="r_knee_link" pos="-0.000372039 5e-05 -0.0968862">
            <inertial pos="0.00334266 0.0196474 -0.0425049" quat="0.999535 -0.000104839 -0.0304236 0.0019934" mass="0.045" diaginertia="6.75039e-05 5.49998e-05 2.05563e-05"/>
            <joint name="r_knee" pos="0 0 0" axis="0 -1 0" range="-2.09 2.09"  />
            <geom type="mesh" rgba="0.4 0.9 0.4 1" mesh="r_knee_link"/>
            <body name="r_ank_pitch_link" pos="0.00103699 0 -0.0890766">
              <inertial pos="-0.017544 0.0195632 0.0134182" quat="0.489309 0.496862 0.510389 0.503197" mass="0.12" diaginertia="7.36835e-05 6.10769e-05 2.91596e-05"/>
              <joint name="r_ank_pitch" pos="0 0 0" axis="0 1 0" range="-2.09 2.09" frictionloss="0.2" />
              <geom type="mesh" rgba="0.4 0.9 0.4 1" mesh="r_ank_pitch_link"/>
              <body name="r_ank_roll_link" pos="-0.0190366 0.02 0.0">
                <inertial pos="0.0285085 -0.0128729 -0.017671" quat="0.0257514 0.696659 0.0389182 0.715883" mass="0.0675" diaginertia="0.000126012 9.21991e-05 4.20891e-05"/>
                <joint name="r_ank_roll" pos="0 0 0" axis="1 0 0" range="-2.09 2.09" frictionloss="0.2" />
                <!-- <geom type="mesh" rgba="0.4 0.9 0.4 1" mesh="r_ank_roll_link" condim="3" contype="1" conaffinity="2"/> -->
                <geom type="box" pos="0.03 -0.015 -0.02" size="0.06 0.04 0.002" rgba="0.4 0.9 0.4 1" contype="1" conaffinity="2"/>

              </body>
            </body>
          </body>
        </body>
      </body>
    </body>
    <body name="head_pan_link" pos="-0.00410029 0 0.1078">
      <inertial pos="0.00549414 0.000156599 0.0141339" quat="0.693159 0.693116 0.139862 -0.139857" mass="0.00767349" diaginertia="2.17841e-06 1.77447e-06 9.86663e-07"/>
      <joint name="head_pan" pos="0 0 0" axis="0 0 -1" range="-2.09 2.09"  damping="0.02"/>
      <geom type="mesh" rgba="0.4 0.9 0.4 1" mesh="head_pan_link"/>
      <body name="head_tilt_link" pos="0.00904595 -0.0185734 0.0281579">
        <inertial pos="0.0113381 0.0189173 0.0221227" quat="0.00744474 0.879474 -0.0114416 0.475751" mass="0.0262249" diaginertia="7.42721e-06 6.32366e-06 5.6713e-06"/>
        <joint name="head_tilt" pos="0 0 0" axis="0 -1 0" range="-2.09 2.09"  damping="0.02"/>
        <geom type="mesh" rgba="0.4 0.9 0.4 1" mesh="head_tilt_link"/>
      </body>
    </body>
    <body name="r_sho_pitch_link" pos="-5.46274e-05 -0.052491 0.087448">
      <inertial pos="0.000375793 -0.0113307 2.09986e-06" quat="-0.00954592 0.707042 0.00954592 0.707042" mass="0.0128" diaginertia="5.03e-06 3.90135e-06 2.04865e-06"/>
      <joint name="r_sho_pitch" pos="0 0 0" axis="0 -1 0" range="-2.09 2.09"  frictionloss="0.2"/>
      <geom type="mesh" rgba="0.4 0.9 0.4 1" mesh="r_sho_pitch_link"/>
      <body name="r_sho_roll_link" pos="0.0200035 -0.021506 0" quat="0.707388 0.706825 0 0">
        <inertial pos="-0.0205038 -0.0278388 -6.10732e-05" quat="0.428351 0.520926 -0.479863 0.561144" mass="0.121" diaginertia="7.5398e-05 7.4522e-05 2.37399e-05"/>
        <joint name="r_sho_roll" pos="0 0 0" axis="1 0 0" range="-2.09 2.09"  frictionloss="0.2"/>
        <geom type="mesh" rgba="0.4 0.9 0.4 1" mesh="r_sho_roll_link"/>
        <body name="r_el_pitch_link" pos="-0.0200035 -0.0741099 0">
          <inertial pos="-0.00697553 -0.0128964 0.000205171" quat="0.20604 0.650508 -0.249985 0.686945" mass="0.045" diaginertia="1.05425e-05 8.79567e-06 7.46187e-06"/>
          <joint name="r_el_pitch" pos="0 0 0" axis="0 -1 0" range="-2.09 2.09"  frictionloss="0.2"/>
          <geom type="mesh" rgba="0.4 0.9 0.4 1" mesh="r_el_pitch_link"/>
          <body name="r_el_yaw_link" pos="0.000397813 -0.0170183 0.0190702">
            <inertial pos="-0.000228559 -0.0572724 -0.0138716" quat="0.66352 0.747563 0.0231725 -0.0188373" mass="0.102" diaginertia="0.000143205 0.000142106 2.94195e-05"/>
            <joint name="r_el_yaw" pos="0 0 0" axis="0 0 1" range="-2.09 2.09"  frictionloss="0.2"/>
            <geom quat="1 0 0 0" type="mesh" rgba="0.4 0.9 0.4 1" mesh="r_el_yaw_link"/>
            <body name="r_gripper_link" pos="0.0198902 -0.0892356 -0.0190702">
              <inertial pos="-0.0193851 -0.00931115 -0.00543048" quat="0.15915 0.685412 0.178235 0.687833" mass="0.0135" diaginertia="6.51914e-06 3.96161e-06 3.27925e-06"/>
              <joint name="r_gripper" pos="0 0 0" axis="1 0 0" range="-2.09 2.09"  frictionloss="0.2"/>
              <geom type="mesh" rgba="0.4 0.9 0.4 1" mesh="r_gripper_link"/>
            </body>
          </body>
        </body>
      </body>
    </body>
    <body name="l_sho_pitch_link" pos="-5.4627e-05 0.052491 0.087448">
      <inertial pos="0.000375774 0.0113303 1.96337e-06" quat="0.00954592 0.707042 -0.00954592 0.707042" mass="0.0128" diaginertia="5.03e-06 3.90135e-06 2.04865e-06"/>
      <joint name="l_sho_pitch" pos="0 0 0" axis="0 -1 0" range="-2.09 2.09"  frictionloss="0.2"/>
      <geom type="mesh" rgba="0.4 0.9 0.4 1" mesh="l_sho_pitch_link"/>
      <body name="l_sho_roll_link" pos="0.020003 0.021507 0" quat="0.707388 -0.706825 0 0">
        <inertial pos="-0.020504 0.027838 -6.0431e-05" quat="0.520926 0.428351 -0.561144 0.479863" mass="0.121" diaginertia="7.5398e-05 7.4522e-05 2.37399e-05"/>
        <joint name="l_sho_roll" pos="0 0 0" axis="1 0 0" range="-2.09 2.09"  frictionloss="0.2"/>
        <geom type="mesh" rgba="0.4 0.9 0.4 1" mesh="l_sho_roll_link"/>
        <body name="l_el_pitch_link" pos="-0.020003 0.074109 0">
          <inertial pos="-0.0069756 0.012896 0.0002073" quat="-0.20604 0.650508 0.249985 0.686945" mass="0.045" diaginertia="1.05425e-05 8.79567e-06 7.46187e-06"/>
          <joint name="l_el_pitch" pos="0 0 0" axis="0 -1 0" range="-2.09 2.09"  frictionloss="0.2"/>
          <geom type="mesh" rgba="0.4 0.9 0.4 1" mesh="l_el_pitch_link"/>
          <body name="l_el_yaw_link" pos="0.00039506 0.017019 0.019072">
            <inertial pos="-0.00022583 0.0572712 -0.0138703" quat="0.747563 0.66352 0.0188373 -0.0231725" mass="0.102" diaginertia="0.000143205 0.000142106 2.94195e-05"/>
            <joint name="l_el_yaw" pos="0 0 0" axis="0 0 1" range="-2.09 2.09"  frictionloss="0.2"/>
            <geom quat="1 0 0 0" type="mesh" rgba="0.4 0.9 0.4 1" mesh="l_el_yaw_link"/>
            <body name="l_gripper_link" pos="0.019893 0.089232 -0.019072">
              <inertial pos="-0.019384 0.0093137 -0.005426" quat="-0.15915 0.685412 -0.178235 0.687833" mass="0.0135" diaginertia="6.51914e-06 3.96161e-06 3.27925e-06"/>
              <joint name="l_gripper" pos="0 0 0" axis="1 0 0" range="-2.09 2.09"  frictionloss="0.2"/>
              <geom type="mesh" rgba="0.4 0.9 0.4 1" mesh="l_gripper_link"/>
            </body>
          </body>
        </body>
      </body>
    </body>
   </body> 
  </worldbody>
  <actuator>
    <motor name="l_hip_yaw" joint="l_hip_yaw" gear="1" ctrllimited="true" ctrlrange="-6 6"/>
    <motor name="l_hip_roll" joint="l_hip_roll" gear="1" ctrllimited="true" ctrlrange="-6 6"/>
    <motor name="l_hip_pitch" joint="l_hip_pitch" gear="1" ctrllimited="true" ctrlrange="-6 6"/>
    <motor name="l_knee" joint="l_knee" gear="1" ctrllimited="true" ctrlrange="-6 6"/>
    <motor name="l_ank_pitch" joint="l_ank_pitch" gear="1" ctrllimited="true" ctrlrange="-6 6"/>
    <motor name="l_ank_roll" joint="l_ank_roll" gear="1" ctrllimited="true" ctrlrange="-6 6"/>
    <motor name="r_hip_yaw" joint="r_hip_yaw" gear="1" ctrllimited="true" ctrlrange="-6 6"/>
    <motor name="r_hip_roll" joint="r_hip_roll" gear="1" ctrllimited="true" ctrlrange="-6 6"/>
    <motor name="r_hip_pitch" joint="r_hip_pitch" gear="1" ctrllimited="true" ctrlrange="-6 6"/>
    <motor name="r_knee" joint="r_knee" gear="1" ctrllimited="true" ctrlrange="-6 6"/>
    <motor name="r_ank_pitch" joint="r_ank_pitch" gear="1" ctrllimited="true" ctrlrange="-6 6"/>
    <motor name="r_ank_roll" joint="r_ank_roll" gear="1" ctrllimited="true" ctrlrange="-6 6"/>
  </actuator>
    <sensor>
      <actuatorpos name='l_hip_yaw'  actuator='l_hip_yaw' user='13'/>
      <actuatorpos name='l_hip_roll'  actuator='l_hip_roll' user='13'/>
      <actuatorpos name='l_hip_pitch'  actuator='l_hip_pitch' user='13'/>
      <actuatorpos name='l_knee'  actuator='l_knee' user='13'/>
      <actuatorpos name='l_ank_pitch'  actuator='l_ank_pitch' user='13'/>
      <actuatorpos name='l_ank_roll'  actuator='l_ank_roll' user='13'/>
      <actuatorpos name='r_hip_yaw'  actuator='r_hip_yaw' user='13'/>
      <actuatorpos name='r_hip_roll'  actuator='r_hip_roll' user='13'/>
      <actuatorpos name='r_hip_pitch'  actuator='r_hip_pitch' user='13'/>
      <actuatorpos name='r_knee'  actuator='r_knee' user='13'/>
      <actuatorpos name='r_ank_pitch'  actuator='r_ank_pitch' user='13'/>
      <actuatorpos name='r_ank_roll'  actuator='r_ank_roll' user='13'/>

      <actuatorvel name='l_hip_yaw_v'  actuator='l_hip_yaw' user='13'/>
      <actuatorvel name='l_hip_roll_v'  actuator='l_hip_roll' user='13'/>
      <actuatorvel name='l_hip_pitch_v'  actuator='l_hip_pitch' user='13'/>
      <actuatorvel name='l_knee_v'  actuator='l_knee' user='13'/>
      <actuatorvel name='l_ank_pitch_v'  actuator='l_ank_pitch' user='13'/>
      <actuatorvel name='l_ank_roll_v'  actuator='l_ank_roll' user='13'/>
      <actuatorvel name='r_hip_yaw_v'  actuator='r_hip_yaw' user='13'/>
      <actuatorvel name='r_hip_roll_v'  actuator='r_hip_roll' user='13'/>
      <actuatorvel name='r_hip_pitch_v'  actuator='r_hip_pitch' user='13'/>
      <actuatorvel name='r_knee_v'  actuator='r_knee' user='13'/>
      <actuatorvel name='r_ank_pitch_v'  actuator='r_ank_pitch' user='13'/>
      <actuatorvel name='r_ank_roll_v'  actuator='r_ank_roll' user='13'/>

      <actuatorfrc name='l_hip_yaw_f'  actuator='l_hip_yaw' user='13' noise='1e-3'/>
      <actuatorfrc name='l_hip_roll_f'  actuator='l_hip_roll' user='13' noise='1e-3'/>
      <actuatorfrc name='l_hip_pitch_f'  actuator='l_hip_pitch' user='13' noise='1e-3'/>
      <actuatorfrc name='l_knee_f'  actuator='l_knee' user='13' noise='1e-3'/>
      <actuatorfrc name='l_ank_pitch_f'  actuator='l_ank_pitch' user='13' noise='1e-3'/>
      <actuatorfrc name='l_ank_roll_f'  actuator='l_ank_roll' user='13' noise='1e-3'/>
      <actuatorfrc name='r_hip_yaw_f'  actuator='r_hip_yaw' user='13' noise='1e-3'/>
      <actuatorfrc name='r_hip_roll_f'  actuator='r_hip_roll' user='13' noise='1e-3'/>
      <actuatorfrc name='r_hip_pitch_f'  actuator='r_hip_pitch' user='13' noise='1e-3'/>
      <actuatorfrc name='r_knee_f'  actuator='r_knee' user='13' noise='1e-3'/>
      <actuatorfrc name='r_ank_pitch_f'  actuator='r_ank_pitch' user='13' noise='1e-3'/>
      <actuatorfrc name='r_ank_roll_f'  actuator='r_ank_roll' user='13' noise='1e-3'/>

      <framequat     name='orientation' objtype='site' noise='0.001' objname='imu'/>
      <framepos     name='position' objtype='site' noise='0.001' objname='imu'/>
      <gyro          name='angular-velocity'    site='imu' noise='0.005' />
      <velocimeter   name='linear-velocity'     site='imu' noise='0.001' />
      <accelerometer name='linear-acceleration' site='imu' noise='0.005' />
      <magnetometer  name='magnetometer'        site='imu'/>
    </sensor>
</mujoco>
